<sdf version='1.7'>
  <world name='default'>
    <light name='sun' type='directional'>
      <cast_shadows>1</cast_shadows>
      <pose>0 0 10 0 -0 0</pose>
      <diffuse>1 1 1 1</diffuse>
      <specular>0.2 0.2 0.2 1</specular>
      <attenuation>
        <range>1000</range>
        <constant>0.9</constant>
        <linear>0.01</linear>
        <quadratic>0.001</quadratic>
      </attenuation>
      <direction>-0.5 -0.5 -1</direction>
      <spot>
        <inner_angle>0</inner_angle>
        <outer_angle>0</outer_angle>
        <falloff>0</falloff>
      </spot>
    </light>
    <physics name='default_physics' default='0' type='ode'>
      <max_step_size>0.001</max_step_size>
      <real_time_factor>1</real_time_factor>
      <real_time_update_rate>1000</real_time_update_rate>
    </physics>
    <scene>
      <ambient>1 1 1 1</ambient>
      <background>1 1 1 1</background>
      <shadows>1</shadows>
    </scene>
    <spherical_coordinates>
      <surface_model>EARTH_WGS84</surface_model>
      <latitude_deg>0</latitude_deg>
      <longitude_deg>0</longitude_deg>
      <elevation>0</elevation>
      <heading_deg>0</heading_deg>
    </spherical_coordinates>
    <state world_name='default'>
      <sim_time>756 637000000</sim_time>
      <real_time>154 692295995</real_time>
      <wall_time>1716209055 991361378</wall_time>
      <iterations>102164</iterations>
      <model name='Marker1'>
        <pose>3.86033 1.11377 -0.295279 0 -0 0</pose>
        <scale>1 1 1</scale>
        <link name='link'>
          <pose>3.86033 1.11377 -0.295279 0 -0 0</pose>
          <velocity>0 0 0 0 -0 0</velocity>
          <acceleration>0 0 0 0 -0 0</acceleration>
          <wrench>0 0 0 0 -0 0</wrench>
        </link>
      </model>
      <model name='Marker2'>
        <pose>6.53229 4.04646 0.264414 0 -0 0.640228</pose>
        <scale>1 1 1</scale>
        <link name='link'>
          <pose>6.53229 4.04646 0.264414 0 -0 0.640228</pose>
          <velocity>0 0 0 0 -0 0</velocity>
          <acceleration>0 0 0 0 -0 0</acceleration>
          <wrench>0 0 0 0 -0 0</wrench>
        </link>
      </model>
      <model name='Marker3'>
        <pose>13.4276 5.19979 -0.59814 0 -0 0</pose>
        <scale>1 1 1</scale>
        <link name='link'>
          <pose>13.4276 5.19979 -0.59814 0 -0 0</pose>
          <velocity>0 0 0 0 -0 0</velocity>
          <acceleration>0 0 0 0 -0 0</acceleration>
          <wrench>0 0 0 0 -0 0</wrench>
        </link>
      </model>
      <model name='inspection_geom'>
        <pose>0 0 0 0 -0 0</pose>
        <scale>1 1 1</scale>
        <link name='inspection_world_link'>
          <pose>0 0 0 0 -0 0</pose>
          <velocity>0 0 0 0 -0 0</velocity>
          <acceleration>0 0 0 0 -0 0</acceleration>
          <wrench>0 0 0 0 -0 0</wrench>
        </link>
      </model>
      <model name='inspection_water_geom'>
        <pose>0.053227 0.002117 0 0 -0 0</pose>
        <scale>1 1 1</scale>
        <link name='inspection_water_link'>
          <pose>0.053227 0.002117 0 0 -0 0</pose>
          <velocity>0 0 0 0 -0 0</velocity>
          <acceleration>0 0 0 0 -0 0</acceleration>
          <wrench>0 0 0 0 -0 0</wrench>
        </link>
      </model>
      <light name='sun'>
        <pose>0 0 10 0 -0 0</pose>
      </light>
    </state>
    <gui fullscreen='0'>
      <camera name='user_camera'>
        <pose>0.738483 -1.44633 0.846442 -0 -0.06727 0.445448</pose>
        <view_controller>orbit</view_controller>
        <projection_type>perspective</projection_type>
      </camera>
    </gui>
    <gravity>0 0 -9.8</gravity>
    <magnetic_field>6e-06 2.3e-05 -4.2e-05</magnetic_field>
    <atmosphere type='adiabatic'/>
    <audio>
      <device>default</device>
    </audio>
    <wind/>
    <model name='inspection_water_geom'>
      <link name='inspection_water_link'>
        <pose>0 0 0 0 -0 0</pose>
        <inertial>
          <pose>0 0 0 0 -0 0</pose>
          <mass>1</mass>
          <inertia>
            <ixx>1</ixx>
            <ixy>0</ixy>
            <ixz>0</ixz>
            <iyy>1</iyy>
            <iyz>0</iyz>
            <izz>1</izz>
          </inertia>
        </inertial>
        <visual name='inspection_water_link_visual'>
          <pose>0 0 0 0 -0 0</pose>
          <geometry>
            <mesh>
              <scale>1 1 1</scale>
              <uri>../models/cpr_inspection/meshes/inspection_water.dae</uri>
            </mesh>
          </geometry>
        </visual>
        <self_collide>0</self_collide>
        <enable_wind>0</enable_wind>
        <kinematic>0</kinematic>
      </link>
      <static>1</static>
      <pose>0 0 0 0 -0 0</pose>
    </model>
    <model name='inspection_geom'>
      <link name='inspection_world_link'>
        <pose>0 0 0 0 -0 0</pose>
        <inertial>
          <pose>0 0 0 0 -0 0</pose>
          <mass>1</mass>
          <inertia>
            <ixx>1</ixx>
            <ixy>0</ixy>
            <ixz>0</ixz>
            <iyy>1</iyy>
            <iyz>0</iyz>
            <izz>1</izz>
          </inertia>
        </inertial>
        <collision name='inspection_world_link_collision'>
          <pose>0 0 0 0 -0 0</pose>
          <geometry>
            <mesh>
              <scale>1 1 1</scale>
              <uri>../models/cpr_inspection/meshes/inspection_world.dae</uri>
            </mesh>
          </geometry>
          <max_contacts>10</max_contacts>
          <surface>
            <contact>
              <ode/>
            </contact>
            <bounce/>
            <friction>
              <torsional>
                <ode/>
              </torsional>
              <ode/>
            </friction>
          </surface>
        </collision>
        <visual name='inspection_world_link_visual'>
          <pose>0 0 0 0 -0 0</pose>
          <geometry>
            <mesh>
              <scale>1 1 1</scale>
              <uri>../models/cpr_inspection/meshes/inspection_world.dae</uri>
            </mesh>
          </geometry>
        </visual>
        <self_collide>0</self_collide>
        <enable_wind>0</enable_wind>
        <kinematic>0</kinematic>
      </link>
      <static>1</static>
      <pose>0 0 0 0 -0 0</pose>
    </model>
    <model name='my_robot_model'>
      <link name='dummy_link'>
        <inertial>
          <pose>0.000499 0 0.0501 0 -0 0</pose>
          <mass>5.01</mass>
          <inertia>
            <ixx>0.0364416</ixx>
            <ixy>0</ixy>
            <ixz>-0.00012475</ixz>
            <iyy>0.11519</iyy>
            <iyz>0</iyz>
            <izz>0.131832</izz>
          </inertia>
        </inertial>
        <collision name='dummy_link_fixed_joint_lump__base_link_collision'>
          <pose>0 0 0.05 0 -0 0</pose>
          <geometry>
            <box>
              <size>0.5 0.25 0.15</size>
            </box>
          </geometry>
          <surface>
            <contact>
              <ode/>
            </contact>
            <friction>
              <ode/>
              <torsional>
                <ode/>
              </torsional>
            </friction>
            <bounce/>
          </surface>
          <max_contacts>10</max_contacts>
        </collision>
        <collision name='dummy_link_fixed_joint_lump__imu_link_collision_1'>
          <pose>0.25 0 0.1 0 -0 0</pose>
          <geometry>
            <box>
              <size>0.02 0.02 0.02</size>
            </box>
          </geometry>
          <surface>
            <contact>
              <ode/>
            </contact>
            <friction>
              <ode/>
              <torsional>
                <ode/>
              </torsional>
            </friction>
            <bounce/>
          </surface>
          <max_contacts>10</max_contacts>
        </collision>
        <visual name='dummy_link_fixed_joint_lump__base_visual_visual'>
          <pose>0 0 0.05 0 -0 0</pose>
          <geometry>
            <box>
              <size>0.5 0.25 0.15</size>
            </box>
          </geometry>
        </visual>
        <visual name='dummy_link_fixed_joint_lump__camera_visual_visual_1'>
          <pose>0.1 0 0.2 0 -0 0</pose>
          <geometry>
            <box>
              <size>0.05 0.05 0.05</size>
            </box>
          </geometry>
          <material>
            <script>
              <name>Gazebo/Blue</name>
              <uri>file://media/materials/scripts/gazebo.material</uri>
            </script>
          </material>
        </visual>
        <visual name='dummy_link_fixed_joint_lump__imu_link_visual_2'>
          <pose>0.25 0 0.1 0 -0 0</pose>
          <geometry>
            <box>
              <size>0.02 0.02 0.02</size>
            </box>
          </geometry>
        </visual>
        <visual name='dummy_link_fixed_joint_lump__lidar_visual_visual_3'>
          <pose>0.1 0 0.2 0 -0 1.5708</pose>
          <geometry>
            <box>
              <size>0.05 0.05 0.05</size>
            </box>
          </geometry>
          <material>
            <script>
              <name>Gazebo/Blue</name>
              <uri>file://media/materials/scripts/gazebo.material</uri>
            </script>
          </material>
        </visual>
        <sensor name='camera_main' type='camera'>
          <update_rate>30</update_rate>
          <camera name='head'>
            <horizontal_fov>1.39626</horizontal_fov>
            <image>
              <width>960</width>
              <height>840</height>
              <format>R8G8B8</format>
            </image>
            <clip>
              <near>0.02</near>
              <far>300</far>
            </clip>
          </camera>
          <plugin name='camera_controller' filename='libgazebo_ros_camera.so'>
            <alwaysOn>1</alwaysOn>
            <updateRate>0.0</updateRate>
            <cameraName>cart_robot/camera_main</cameraName>
            <imageTopicName>image_raw</imageTopicName>
            <cameraInfoTopicName>camera_info</cameraInfoTopicName>
            <frameName>camera</frameName>
            <hackBaseline>0.07</hackBaseline>
            <distortionK1>0.0</distortionK1>
            <distortionK2>0.0</distortionK2>
            <distortionK3>0.0</distortionK3>
            <distortionT1>0.0</distortionT1>
            <distortionT2>0.0</distortionT2>
            <robotNamespace>/</robotNamespace>
          </plugin>
          <pose>0.1 0 0.15 0 -0 0</pose>
        </sensor>
        <gravity>1</gravity>
        <sensor name='imu_sensor' type='imu'>
          <always_on>1</always_on>
          <update_rate>100</update_rate>
          <visualize>0</visualize>
          <topic>__default_topic__</topic>
          <plugin name='imu_plugin' filename='libgazebo_ros_imu_sensor.so'>
            <topicName>cart_robot/imu</topicName>
            <bodyName>imu_link</bodyName>
            <updateRateHZ>10.0</updateRateHZ>
            <gaussianNoise>0.0</gaussianNoise>
            <xyzOffset>0 0 0</xyzOffset>
            <rpyOffset>0 0 0</rpyOffset>
            <frameName>imu_link</frameName>
            <initialOrientationAsReference>0</initialOrientationAsReference>
            <robotNamespace>/</robotNamespace>
          </plugin>
          <imu>
            <angular_velocity>
              <x>
                <noise type='gaussian'>
                  <mean>0</mean>
                  <stddev>0.0002</stddev>
                  <bias_mean>7.5e-06</bias_mean>
                  <bias_stddev>8e-07</bias_stddev>
                </noise>
              </x>
              <y>
                <noise type='gaussian'>
                  <mean>0</mean>
                  <stddev>0.0002</stddev>
                  <bias_mean>7.5e-06</bias_mean>
                  <bias_stddev>8e-07</bias_stddev>
                </noise>
              </y>
              <z>
                <noise type='gaussian'>
                  <mean>0</mean>
                  <stddev>0.0002</stddev>
                  <bias_mean>7.5e-06</bias_mean>
                  <bias_stddev>8e-07</bias_stddev>
                </noise>
              </z>
            </angular_velocity>
            <linear_acceleration>
              <x>
                <noise type='gaussian'>
                  <mean>0</mean>
                  <stddev>0.017</stddev>
                  <bias_mean>0.1</bias_mean>
                  <bias_stddev>0.001</bias_stddev>
                </noise>
              </x>
              <y>
                <noise type='gaussian'>
                  <mean>0</mean>
                  <stddev>0.017</stddev>
                  <bias_mean>0.1</bias_mean>
                  <bias_stddev>0.001</bias_stddev>
                </noise>
              </y>
              <z>
                <noise type='gaussian'>
                  <mean>0</mean>
                  <stddev>0.017</stddev>
                  <bias_mean>0.1</bias_mean>
                  <bias_stddev>0.001</bias_stddev>
                </noise>
              </z>
            </linear_acceleration>
          </imu>
          <pose>0.25 0 0.1 0 -0 0</pose>
        </sensor>
        <sensor name='lidar_main' type='ray'>
          <visualize>0</visualize>
          <update_rate>40</update_rate>
          <ray>
            <scan>
              <horizontal>
                <samples>180</samples>
                <resolution>1</resolution>
                <min_angle>0</min_angle>
                <max_angle>6.28</max_angle>
              </horizontal>
              <vertical>
                <samples>1</samples>
                <min_angle>0</min_angle>
                <max_angle>0</max_angle>
              </vertical>
            </scan>
            <range>
              <min>0.3</min>
              <max>3</max>
              <resolution>0.01</resolution>
            </range>
            <noise>
              <type>gaussian</type>
              <mean>0</mean>
              <stddev>0.01</stddev>
            </noise>
          </ray>
          <plugin name='gazebo_ros_head_hokuyo_controller' filename='libgazebo_ros_laser.so'>
            <topicName>cart_robot/lidar_main</topicName>
            <frameName>lidar</frameName>
            <robotNamespace>/</robotNamespace>
          </plugin>
          <pose>0.1 0 0.15 0 -0 1.5708</pose>
        </sensor>
        <self_collide>0</self_collide>
        <enable_wind>0</enable_wind>
        <kinematic>0</kinematic>
      </link>
      <joint name='wheel_down_left_joint' type='revolute'>
        <pose relative_to='dummy_link'>-0.25 0.125 -0.075 1.57 -0 0</pose>
        <parent>dummy_link</parent>
        <child>wheel_down_left_link</child>
        <axis>
          <xyz>0 0 1</xyz>
          <limit>
            <effort>50</effort>
            <velocity>100</velocity>
            <lower>-1e+16</lower>
            <upper>1e+16</upper>
          </limit>
          <dynamics>
            <spring_reference>0</spring_reference>
            <spring_stiffness>0</spring_stiffness>
          </dynamics>
        </axis>
      </joint>
      <link name='wheel_down_left_link'>
        <pose relative_to='wheel_down_left_joint'>0 0 0 0 -0 0</pose>
        <inertial>
          <pose>0 0 0.022 0 -0 0</pose>
          <mass>10</mass>
          <inertia>
            <ixx>0.00917583</ixx>
            <ixy>0</ixy>
            <ixz>0</ixz>
            <iyy>0.00917583</iyy>
            <iyz>0</iyz>
            <izz>0.015125</izz>
          </inertia>
        </inertial>
        <collision name='wheel_down_left_link_collision'>
          <pose>0 0 0.022 0 -0 0</pose>
          <geometry>
            <cylinder>
              <length>0.044</length>
              <radius>0.055</radius>
            </cylinder>
          </geometry>
          <surface>
            <contact>
              <ode/>
            </contact>
            <friction>
              <ode/>
              <torsional>
                <ode/>
              </torsional>
            </friction>
            <bounce/>
          </surface>
          <max_contacts>10</max_contacts>
        </collision>
        <visual name='wheel_down_left_link_fixed_joint_lump__wheel_down_left_visual_visual'>
          <pose>0 0 0.022 0 -0 0</pose>
          <geometry>
            <cylinder>
              <length>0.044</length>
              <radius>0.055</radius>
            </cylinder>
          </geometry>
        </visual>
        <self_collide>0</self_collide>
        <enable_wind>0</enable_wind>
        <kinematic>0</kinematic>
      </link>
      <joint name='wheel_down_right_joint' type='revolute'>
        <pose relative_to='dummy_link'>-0.25 -0.125 -0.075 1.57 -0 0</pose>
        <parent>dummy_link</parent>
        <child>wheel_down_right_link</child>
        <axis>
          <xyz>0 0 1</xyz>
          <limit>
            <effort>50</effort>
            <velocity>100</velocity>
            <lower>-1e+16</lower>
            <upper>1e+16</upper>
          </limit>
          <dynamics>
            <spring_reference>0</spring_reference>
            <spring_stiffness>0</spring_stiffness>
          </dynamics>
        </axis>
      </joint>
      <link name='wheel_down_right_link'>
        <pose relative_to='wheel_down_right_joint'>0 0 0 0 -0 0</pose>
        <inertial>
          <pose>0 0 -0.022 0 -0 0</pose>
          <mass>10</mass>
          <inertia>
            <ixx>0.00917583</ixx>
            <ixy>0</ixy>
            <ixz>0</ixz>
            <iyy>0.00917583</iyy>
            <iyz>0</iyz>
            <izz>0.015125</izz>
          </inertia>
        </inertial>
        <collision name='wheel_down_right_link_collision'>
          <pose>0 0 -0.022 0 -0 0</pose>
          <geometry>
            <cylinder>
              <length>0.044</length>
              <radius>0.055</radius>
            </cylinder>
          </geometry>
          <surface>
            <contact>
              <ode/>
            </contact>
            <friction>
              <ode/>
              <torsional>
                <ode/>
              </torsional>
            </friction>
            <bounce/>
          </surface>
          <max_contacts>10</max_contacts>
        </collision>
        <visual name='wheel_down_right_link_fixed_joint_lump__wheel_down_right_visual_visual'>
          <pose>0 0 -0.022 0 -0 0</pose>
          <geometry>
            <cylinder>
              <length>0.044</length>
              <radius>0.055</radius>
            </cylinder>
          </geometry>
        </visual>
        <self_collide>0</self_collide>
        <enable_wind>0</enable_wind>
        <kinematic>0</kinematic>
      </link>
      <joint name='wheel_up_left_joint' type='revolute'>
        <pose relative_to='dummy_link'>0.25 0.125 -0.075 1.57 -0 0</pose>
        <parent>dummy_link</parent>
        <child>wheel_up_left_link</child>
        <axis>
          <xyz>0 0 1</xyz>
          <limit>
            <effort>50</effort>
            <velocity>100</velocity>
            <lower>-1e+16</lower>
            <upper>1e+16</upper>
          </limit>
          <dynamics>
            <spring_reference>0</spring_reference>
            <spring_stiffness>0</spring_stiffness>
          </dynamics>
        </axis>
      </joint>
      <link name='wheel_up_left_link'>
        <pose relative_to='wheel_up_left_joint'>0 0 0 0 -0 0</pose>
        <inertial>
          <pose>0 0 0.022 0 -0 0</pose>
          <mass>10</mass>
          <inertia>
            <ixx>0.00917583</ixx>
            <ixy>0</ixy>
            <ixz>0</ixz>
            <iyy>0.00917583</iyy>
            <iyz>0</iyz>
            <izz>0.015125</izz>
          </inertia>
        </inertial>
        <collision name='wheel_up_left_link_collision'>
          <pose>0 0 0.022 0 -0 0</pose>
          <geometry>
            <cylinder>
              <length>0.044</length>
              <radius>0.055</radius>
            </cylinder>
          </geometry>
          <surface>
            <contact>
              <ode/>
            </contact>
            <friction>
              <ode/>
              <torsional>
                <ode/>
              </torsional>
            </friction>
            <bounce/>
          </surface>
          <max_contacts>10</max_contacts>
        </collision>
        <visual name='wheel_up_left_link_fixed_joint_lump__wheel_up_left_visual_visual'>
          <pose>0 0 0.022 0 -0 0</pose>
          <geometry>
            <cylinder>
              <length>0.044</length>
              <radius>0.055</radius>
            </cylinder>
          </geometry>
        </visual>
        <self_collide>0</self_collide>
        <enable_wind>0</enable_wind>
        <kinematic>0</kinematic>
      </link>
      <joint name='wheel_up_right_joint' type='revolute'>
        <pose relative_to='dummy_link'>0.25 -0.125 -0.075 1.57 -0 0</pose>
        <parent>dummy_link</parent>
        <child>wheel_up_right_link</child>
        <axis>
          <xyz>0 0 1</xyz>
          <limit>
            <effort>50</effort>
            <velocity>100</velocity>
            <lower>-1e+16</lower>
            <upper>1e+16</upper>
          </limit>
          <dynamics>
            <spring_reference>0</spring_reference>
            <spring_stiffness>0</spring_stiffness>
          </dynamics>
        </axis>
      </joint>
      <link name='wheel_up_right_link'>
        <pose relative_to='wheel_up_right_joint'>0 0 0 0 -0 0</pose>
        <inertial>
          <pose>0 0 -0.022 0 -0 0</pose>
          <mass>10</mass>
          <inertia>
            <ixx>0.00917583</ixx>
            <ixy>0</ixy>
            <ixz>0</ixz>
            <iyy>0.00917583</iyy>
            <iyz>0</iyz>
            <izz>0.015125</izz>
          </inertia>
        </inertial>
        <collision name='wheel_up_right_link_collision'>
          <pose>0 0 -0.022 0 -0 0</pose>
          <geometry>
            <cylinder>
              <length>0.044</length>
              <radius>0.055</radius>
            </cylinder>
          </geometry>
          <surface>
            <contact>
              <ode/>
            </contact>
            <friction>
              <ode/>
              <torsional>
                <ode/>
              </torsional>
            </friction>
            <bounce/>
          </surface>
          <max_contacts>10</max_contacts>
        </collision>
        <visual name='wheel_up_right_link_fixed_joint_lump__wheel_up_right_visual_visual'>
          <pose>0 0 -0.022 0 -0 0</pose>
          <geometry>
            <cylinder>
              <length>0.044</length>
              <radius>0.055</radius>
            </cylinder>
          </geometry>
        </visual>
        <self_collide>0</self_collide>
        <enable_wind>0</enable_wind>
        <kinematic>0</kinematic>
      </link>
      <static>0</static>
      <plugin name='gazebo_ros_control' filename='libgazebo_ros_control.so'>
        <robotNamespace>/cart_robot</robotNamespace>
        <robotSimType>gazebo_ros_control/DefaultRobotHWSim</robotSimType>
      </plugin>
      <pose>1 1 0.2 0 -0 0</pose>
    </model>
    <model name='Marker1'>
      <static>1</static>
      <link name='link'>
        <visual name='visual'>
          <geometry>
            <mesh>
              <uri>model://marker1/meshes/Marker1.dae</uri>
              <scale>1 1 1</scale>
            </mesh>
          </geometry>
        </visual>
        <self_collide>0</self_collide>
        <enable_wind>0</enable_wind>
        <kinematic>0</kinematic>
      </link>
      <pose>3.02271 0.397532 0 0 -0 0</pose>
    </model>
    <model name='Marker2'>
      <static>1</static>
      <link name='link'>
        <visual name='visual'>
          <geometry>
            <mesh>
              <uri>model://marker2/meshes/Marker2.dae</uri>
              <scale>1 1 1</scale>
            </mesh>
          </geometry>
        </visual>
        <self_collide>0</self_collide>
        <enable_wind>0</enable_wind>
        <kinematic>0</kinematic>
      </link>
      <pose>5.94961 5.81996 0 0 -0 0</pose>
    </model>
    <model name='Marker3'>
      <static>1</static>
      <link name='link'>
        <visual name='visual'>
          <geometry>
            <mesh>
              <uri>model://marker3/meshes/Marker3.dae</uri>
              <scale>1 1 1</scale>
            </mesh>
          </geometry>
        </visual>
        <self_collide>0</self_collide>
        <enable_wind>0</enable_wind>
        <kinematic>0</kinematic>
      </link>
      <pose>13.4276 2.62087 0 0 -0 0</pose>
    </model>
  </world>
</sdf>
